# callbackFlow取消异常

问题：android 协程 callbackFlow  结束 close时会发送取消异常，导致外部会捕获一个异常，这种情况怎么避免，或是我该怎么处理才能绕过这个异常吗？

在实际应用中，我需要在catch中对外通知异常，但callbackFlow会有取消异常，此时需要特殊处理。

## 处理方法

在 Android 协程中使用 `callbackFlow` 时，当调用 `close()` 关闭流时确实会触发 `CancellationException`，这是设计预期行为。以下是几种避免或处理此异常的推荐方案：

---

### 1. **使用 `try/catch` 捕获特定异常（推荐）**

   在收集流的协程中捕获 `CancellationException` 并忽略：

   ```kotlin
   viewModelScope.launch {
       try {
           callbackFlow.collect { value ->
               // 处理数据
           }
       } catch (e: CancellationException) {
           // 忽略流的正常关闭异常
       } catch (e: Exception) {
           // 处理其他异常
       }
   }
   ```

---

### 2. **使用 `flow` 的扩展函数封装处理**

   创建扩展函数自动忽略 `CancellationException`：

   ```kotlin
   suspend fun <T> Flow<T>.collectSafely(block: (T) -> Unit) {
       try {
           collect(block)
       } catch (e: CancellationException) {
           // 忽略
       }
   }

   // 使用：
   viewModelScope.launch {
       callbackFlow.collectSafely { value ->
           // 处理数据
       }
   }
   ```

---

### 3. **检查关闭原因（高级）**

   在 `callbackFlow` 中通过 `close` 的 `cause` 参数明确关闭原因，避免发送取消异常：

   ```kotlin
   callbackFlow {
       val callback = object : SomeCallback {
           override fun onData(data: String) {
               trySend(data)
           }
           override fun onComplete() {
               // 明确指定正常关闭（cause = null）
               close(cause = null) // ✅ 不会触发 CancellationException
           }
       }
       registerCallback(callback)
       awaitClose { unregisterCallback(callback) }
   }
   ```

---

### 4. **使用 `onCompletion` 替代异常捕获**

   通过 `onCompletion` 操作符区分正常关闭与异常：

   ```kotlin
   callbackFlow
       .onCompletion { cause ->
           if (cause is CancellationException) {
               // 流被取消，可能是正常结束
           } else if (cause != null) {
               // 真实异常
           }
       }
       .collect { /* ... */ }
   ```

---

### 5. **使用 `catch` 操作符（不推荐用于取消）**
   >
   > ⚠️ 注意：`catch` 无法捕获下游（collect 中）的异常，对 `CancellationException` 无效。

---

### 关键理解

- **`CancellationException` 是协程取消的正常机制**，通常无需视为错误。
- 当 `callbackFlow` 的 `close()` 被调用时：
  - 默认会发送 `CancellationException("Flow was aborted, no more elements needed")`。
  - 通过 `close(cause = null)` 可避免此异常。
- 在 Android 生命周期中（如 `viewModelScope`），协程取消是常态，无需处理此异常。

---

### 完整示例：安全关闭的 callbackFlow

```kotlin
fun observeData(): Flow<String> = callbackFlow {
    val callback = object : DataCallback {
        override fun onUpdate(data: String) {
            trySend(data)
        }
        override fun onFinished() {
            close(cause = null) // ✅ 安全关闭，不抛异常
        }
    }

    registerCallback(callback)
    awaitClose { unregisterCallback(callback) }
}

// 收集端
viewModelScope.launch {
    try {
        observeData().collect { data ->
            // 更新 UI
        }
    } catch (e: CancellationException) {
        // 可选：记录日志或忽略
    }
}
```

通过上述方案，可有效避免因 `callbackFlow` 关闭导致的异常干扰。根据场景选择最合适的处理方式即可。
